Workbook
Name Tapezierarbeiten: Leistungen!$C$15:$N$18
Name Tapezieren: Leistungen!$C$11:$N$18
Name Türen: Leistungen!$C$25:$N$28

Sheet Berechnung Vorgehen
A1: e
A2: Abfolge | B2: Kathegorie | C2: Objekt | D2: Schritte | E2: Regeln | F2: Definition | G2: möglicher Code | H2: Formel in Worten und Sinn | I2: Auswirkung auf | J2: Regel-Typ | K2: Quelle | L2: UX-Beschreibung | M2: Objekt | O2: Objekt | P2: Mengen-Grundlage | Q2: Objektangabe Kunde | R2: Formel | S2: Menge | T2: Faktor | U2: Leistung | V2: Sonderleistung | W2: U-leistung
A3: 1 | B3: Leistung | C3: Alle Objekte | D3: Je Objekt ausgewählte Leistung aufführen und prüfen ob Unterleistungen angehängt sind | L3: Als erstes sollen die ausgewählten Leistungen inklusive der angehängten unterLeistungen aufgeführt werden | O3: Wohnzimmer | P3: 15 | Q3: Flur
A4: 3 | B4: Mengen | C4: Raum | D4: Mengenberechnung Decke Je Raum | E4: Ist m² Grundfläche | H4: Ist m² Grundfläche | I4: Preisrahmen, Zeitrahmen | K4: Angabe Verbraucher Shop | L4: Für die Berechnung der Decken Fläche wird die Angabe der Quadratmeter Grundfläche in den Räumen herangezogen und eins zu eins übernommen | Q4: L
A5: 4 | B5: Mengen | C5: Raum, Leisten | D5: Mengenberechnung Raumumfang Je Raum | H5: 4xWurzel(m² Grundfläche) | I5: Preisrahmen, Zeitrahmen | K5: Admnin SE | L5: Um den Umfang eines Raumes zu berechnen, wird die Wurzel Quadratmeter Grundfläche mal vier genommen, woraus ich eine Zahl mit Einheit m ergibt | Q5: Treppenhaus
A6: 5 | B6: Mengen, Leistung | C6: Alle Objekte | D6: Prüfen auf Objekttyp mit Faktoren | F6: Grundfläche m² x Faktor | H6: Grundfläche m² x Faktor | I6: Preisrahmen, Zeitrahmen | K6: Admin SE und Onboarding | L6: Bei jedem Objekttyp ist zu prüfen, ob auf diesen ein Faktor belegt ist zum Beispiel bei Räumen. Die Grundrissart wie ein Quadrat hat keinen Faktor beziehungsweise Faktor 1. ein L, ein Flur hat einen Faktor. auch ein Bad und ein Treppenhaus haben ein Faktor. Hierbei ist gleichzeitig zu prüfen, ob es sich um einen Faktor Dreht, der auf Mengen wie bei dem Grundrissfaktor also L oder Flur handelt oder Quadrat bezieht oder auf einen Leistungsfaktoren bezieht, was den Schwierigkeitsgrad darstellt. Im Bad ist es schwieriger zu arbeiten wegen der Installationen. Somit bezieht sich der Faktor hier nicht auf die Mengen, sondern nur auf die zu erbringenden Leistungen. Genauso verhält sich dies beim Treppenhaus, wo sich der Faktor ebenfalls auf die Leistung bezieht. Falls ein Objekttyp sowohl eine Multiplikator mit Mengenbezug als auch Leistungsbezug hinterlegt hat, werden beide in die Berechnung mit einbezogen. Erst der Mengenfaktor und dann der Leistungsfaktor | Q6: Bad
A7: 6 | B7: Mengen | C7: Raum | D7: Je Raum Mengenbrechnung der Wandflächen | F7: Umfang x Raumhöhe (Abzug Bauteile wird nicht berücksichtigt) | H7: U x H | I7: Preisrahmen, Zeitrahmen | K7: Admin SE und Angabe Verbraucher Shop | L7: Für die Berechnung der Wandflächen wird der errechnete und mit Faktoren multiplizierte Umfang herangezogen und mit der Höhe des Raumes multipliziert. Dabei werden aktuell keine Bauteile wie Fenster oder Türen von der Menge abgezogen.falls doch hohe Genauigkeit gefordert wird, könnten getrennt betrachtete Flächengrößen über 2,5 m² abgezogen wrden. Wenn dieser Vorgang bevorzugt wird, müssten allerdings sämtliche Flächen der Bauteile wie Fenster und Türen in die Position "abdecken", mit einbezogen werden | Q7: Küche
A8: 7 | B8: Leistung | C8: Alle Objekte | D8: Prüfen auf Sonderangaben zu Objekt | F8: Mengeneinheit (z.B. 40m² Decken und Wandflächen) x kalkulierte Zeit der Leistung je Einheit x Faktor Erschwernisgrad auf Sonderangaben | H8: Mengeneinheiten x T Leistung x Faktor Erschwernisgrad | I8: Preisrahmen, Zeitrahmen | K8: Onboardingund Angabe Verbraucher Shop | L8: Hierbei handelt es sich um Angaben der Verbraucher auf der Shop Seite zu den Objekten. Beispielsweise Stuck an der Decke, Nikotin auf der Oberfläche, vergraute/verschmutzte Oberfläche, getönter Untergrund bei Auswahl <Leistung "Überholunganstrich" etc. Aber auch bei Fenster die Auswahl Sprossenfenster. Der Faktor für den Erschwernisgrad wurde im Onboarding durch das Unternehmen festgelegt. Dieser wird mit der zugehörigen Leistung multipliziert | Q8: Stuck
A9: 6 | B9: Leistung | C9: Alle Objekte | D9: Baseline heranziehen | E9: Baseline-Zeit | F9: Zeit/Einheit eines Standart-Kalk-Fall | H9: T für Standartfall/MengeStandartfall | I9: Preisrahmen, Zeitrahmen | J9: Global | K9: Onboarding Leistung | L9: Die baseline Zeit. Bezieht sich auf. Den. Für die. Jeweilige Leistung individuell herangezogenen Standardfall. Im Onboarding beziehungsweise in den vorhandenen, zur Verfügung gestellten Daten für die Betriebe, ist ein Standardfall hinterlegt. Zum Beispiel für das Streichen eines Zimmers mit 40 Quadratmetern braucht einen Mitarbeiter. 3 Stunden. Die Betriebe können jedoch. Die individuell ihre Standardfälle definieren. Zum Beispiel könnte für einen anderen Betrieb. Der ein Standardfall. 2 Zimmer mit in Summe. 100 Quadratmeter sein. Wofür ein Mitarbeiter 5 Stunden braucht für einen überholungsanstrich. Im Endeffekt ist es egal. Wichtig ist nur dass hier die Standardkalkulation festgelegt wird, für die ein Betrieb im Normalfall Kalkuliert. Aus der aus dem Standardfall angegebene Menge und der Zeit, ergibt sich die baseline Zeit. Und zwar. die angenommene Zeit im ersten Beispiel 3 Stunden durch die Menge der Einheiten, in diesem Fall 40 Quadratmeter, geteilt wird. Das Ergebnis ist die Base Line Zeit je Einheit, in diesem Fall Quadratmeter. also 3h/40m²
A10: 7 | B10: Leistung | C10: Alle Objekte | D10: Effizienzgrad linear identifizieren | F10: ab start → +step_percent je zusätzlichem Element bis cap_value (optional gedeckelt durch max_percent) maximale Einheiten am Tag = Grenzeffektivität | H10: 1. Effektivitätsmenge + 2. Effektivitätsmenge +3. Effektivitätsmenge...) bis Summe der Effektivitätsmengen auf "MaxProdTagEinheiten" trifft -> T_Tag(8h)/MaxProduktivitätTagEinheiten(150m²) | I10: Preisrahmen, Zeitrahmen | K10: Onboarding Leistung | L10: Im Onboarding der Leistungen wird definiert, ab wann eine Standardleistung mit einer Standardkalkulation effizienter wird. Zum Beispiel, ab dem zweiten Raum mit 15 Quadratmeter Grundfläche, also circa 50 Quadratmeter, Decken und Wandfläche Überholungsanstrich, ist eine erhöhte Effizienz zu erkennen. Man könnte auch andersherum sagen, ab 100 Quadratmetern zu streichender Fläche, ist eine erhöhte Effizienz gegenüber der Standardkalkulation zu erkennen (1. Effektivitätsmenge). Steigert sich im gleichen Maße der Vergleichswert als Menge (im Beispiel wieder um 50m²) von der ersten Effizienz, erhöht sich die Effizienz. Die Effizienzen steigern sich linear, bis die Grenze der Effektivität erreicht ist. Diese nach oben hin eingrenzende Grenzeffektivität wird ebenfalls aus dem Onboarding generiert. im Onboarding zur Grenzeffektivität heißt die Frage, wieviel Einheiten schafft ein Mitarbeiter oder Mitarbeiterin am Tag, sprich etwa in 8 Stunden. Um die Grenzeffektivität auf die Ebene der Baseline Zeit zu bringen, teilt man hier wiederum die Zeit durch die angegebenen Einheiten aus dem Onboarding und erhält Zeit je Einheit z.B. T/m² (z.B. ein Mitarbeiter schafft es am Tag 150m² Decken und Wände zu streichen. 8h/150m²=0,0533h/m²) Es ist nun zu Prüfen, wo sich die errechnete Menge der ausgewählten Leistung befindet, um die Effizienzen einzuberechnen. Sobald die dafür benötigte Zeit + die vorweg benötigte Zeit für eine zuvor benötigte Leistung, den Arbeitstag überschreitet, endet der Tag und die Zeitwerte fließen in den nächsten Tag.
A11: 8 | B11: Leistung, Mengen | C11: Alle Objekte | D11: Effizienz Kundenfreigabe erteilt? | F11: Bei Freigabe mehrerer Objekte durch den Verbraucher im Shop, können Effizienzen erreicht werden | H11: Objektfreigabe Kunde = Ja = Effizienzen greifen | I11: Preisrahmen, Zeitrahmen | K11: Angabe Verbraucher im Shop | L11: Damit die zuvor beschriebenen Effizienzen greifen können, muss der Verbraucher zuvor im Shop angegeben haben, dass gleichzeitig an mehreren Objekten mit der gleichen Leistung gearbeitet werden kann. Ansonsten können die Effizienzen nicht freigesetzt werden. Für die Steigerung der Effizienz, hilft es nichts Leistungen zum Mischen, um den Tag zu befüllen. Es ermöglicht den Gesamtzeitrahmen zu kürzen, was jedoch nicht mit einer Effizienzsteigerung einer Leistung gleichzusetzen ist.
A12: 9 | B12: Leistung | C12: Alle Objekte | D12: Warte-/Trocknungszeiten prüfen und Prüfen auf mögliche Parallelarbeit verschiedener Leistungen innerhalb eines Raumes. Weiter um Prüfung, ob Parallelatbeit für die Positionen freigegeben ist | H12: Raum1( LeistungX 6h + Trockenzeit 12h = 18h); Raum1 (LeistungY 1,5h), Leistung X und LeistungY haben gegenseitige Freigabe zur Parallelarbeit -> Raum1(LeistungX 6h + LeistungY 1,5h = 7,5 h an diesem Tag) | I12: Zeitrahmen | K12: Onboarding | L12: Es muss geprüft werden ob für die ausgewählten Leistungen warte- beziehungsweise Trocknungszeiten vorgesehen sind und wie lange diese andauern falls das der Fall ist. Außerdem muss geprüft werden ob andere Leistungen während dieser Warte- beziehungsweise Trocknungszeiten ausgeführt werden können. So darf beispielsweise während der Trocknungsphase einer Lackierung auf einer Tür im gleichen Raum, nicht die Fenster geschliffen werden, da der Staub sich in den noch feuchten Türen festsetzen könnte und die Lackierung damit verunreinigt. Wenn also nach 6 Stunden Arbeit die genannte Tür noch feucht ist und bei den Kunden nur noch Fenster im gleichen Raum zu bearbeiten sind und somit erst einmal geschliffen werden müssen, ist die Arbeit für diesen Tag beendet und kann erst nach Trocknung der Türen am nächsten Tag fortgesetzt werden. Handelt es sich jedoch um eine Leistung die zu anderen Leistungen gegenseitig zur Parallelarbeit freigeschaltet ist, kann die andere Leistungen während der Trocknungsphase der ersten Leistung ausgeführt werden. Außerdem greifen Leistungen in einem anderen Raum nicht in die Trocknungszeiten des anderen Raumes ein. So bedarf zum Beispiel das Abdecken des Bodens keiner Wartezeit für die nächste Leistungen wie etwa das Streichen. Es darf auch in einem Raum ein Fenster geschliffen werden, während in einem anderen Raum noch ein Fenster nach der Lackierung am trocknen ist..
A13: 10 | B13: Leistung | C13: Alle Objekte | D13: Sortierung je Raum nach Abfolge/Workflow der Leistungen | I13: Zeitrahmen | K13: Onboarding | L13: Im Onboarding ist bei den Leistungen anzugeben welche, Leistungen und Unterleistungen aufeinander folgen sollen/können/dürfen. Die durch den Verbraucher im Shop ausgewählten Leistungen werden dann entsprechend im Raum nach Vorgabe des Onboardings sortiert. Diese Abfolge in Kombination mit Ausführungszeiten und Trocknungszeiten, bestimmt was und wieviel an welchen Tagen gearbeitet werden kann und wieviel Tage insgesamt in Anspruch genommen werden können beziehungsweise müssen
A14: 11 | B14: Leistung, Mengen | C14: Alle Objekte | D14: Mehrpersonal Prüfen ob sinnvoll weiteres Personal eingesetzt werden sollte, ohne Effizienzverlust hinnehmen zu müssen | H14: Bei z.B. 1. Effektivitätsmenge + 2. Effektivitätsmenge +3. Effektivitätsmenge = 32h -> 32h/2Mitarbeiter= 16h/Mitarbeiter (max Effizienz wieter gegeben) -> 32h/Mitarbeiter= 11h/Mitarbeiter (max Effizienz je Mitarbeiter wäre hier nur noch für 1Tag(11-8=3h) gegeben. 3 Mitarbeiter machen zur Planung auf diese leistung hin keinen Sinn, könnten jedoch in Kombination mit weiteren Leistungen wieder Sinn ergeben | I14: Zeitrahmen | K14: Onboarding | L14: Im Onboarding ist anzugeben unter welchen Voraussetzungen ein zweiter, dritter oder mehrerer Mitarbeiter eingesetzt werden können. Faktoren dafür können Mengen in Form von Fläche Raum oder Stückzahl sein und die Möglichkeit parallel in verschiedenen Räumen zu arbeiten. Prinzipiell macht es nur Sinn weitere Personen einzusetzen, wenn gleichzeitig unterschiedliche Leistungen und oder unterschiedliche Objekte bearbeitet werden können. Auch sollte sich durch den Mehreinsatz vom Personal die Effizienz der Leistungen nicht reduzieren. Wenn sich also beispielsweise die Effizienzsteigerung beim Streichen eines überholungsanstrich von 2 Räumen mit insgesamt 100 Quadratmetern durch den Einsatz weiteren Personals pulverisiert, macht der Einsatz des weiteren Personals keinen Sinn. Auch macht der Einsatz weiteren Personals keinen Sinn, wenn bei kurzfristigen Arbeiten, eine Leistung die normalerweise knapp einen Tag brauchen würde, durch den Einsatz weiteren Personals nur noch 2 oder 3 Stunden braucht, da dann der Rest des Tages unproduktiv bleibt und somit erhöhte Kosten für den Handwerksunternehmer entstehen. Wenn jedoch die Effizienzgrenze nach oben mehrfach durchbrochen wurde, könnte der Einsatz weiteren Personals Sinn machen, so lange die maximale Effizienz trotz Arbeitsteilung genutzt wäre. Im Onboarding sollte angegeben sein, ab wie viel Stunden Arbeitsleistung für ein Projekt prinzipiell die Überlegung weiteren Personaleinsatzes erlaubt/geplant ist
A15: 12 | D15: Ausgabe der Informationen/Inhalte/Zahlen | L15: Die Ausgabe sollte je Objekt aber auch zusätzlich kumuliert enthalten: sämtliche Leistungen mit Herleitung von Flächenberechnungen sonderangaben, deren Faktoren und Auswirkungen. welche Effizienz warum gezogen wurde . Welche Warte- oder Trocknungszeit sich ausgewirkt haben und wie die Abfolge beziehungsweise der Workflow der Leistungen ist. außerdem welche Objekttypen und damit verbundene verändernden Faktoren angehängt sind. Außerdem sollte insgesamt die Abfolge der Tage aufgezeigt werden und wie viel Mitarbeiter Sinn machen und wie sich mehr Mitarbeiter auswirken.
A16: 13
A17: 14
A18: 15
A19: 16
A20: 17
A21: 18
A22: 19
A23: 20
A24: 21
A25: 22
A26: 23
A27: 24

Sheet Feedback an KhalidKalk
A1: Stand | B1: 15.11. 14:34
A2: Settings | B2: Feedback
A3: Hours per Day | B3: Beachte: Freitag wirdweniger gearbeitet
A4: Min_Efficiency_Factor | B4: Verstehe ich nicht
A5: Max_Employees_Without_Loss | B5: Ich denke das ist schwer global zu sagen. Eher von Projekt zu Projekt
A8: Sonderleistungen | B8: Feedback
A9: Leistungen | B9: es fehlen die automatisch angehängten Unterleistungen einer Shopleistung. Bei Überholungsanstrich: IMMER "Abdecken". Dübellöcher, Stuck
A10: Leistungen | B10: Es fehlt die Eingabemöglichekeit des Zustandes der Oberflächen oder weitere Spezifikationen, wie Verschmutzung und der passende Faktor oder Sonderleistungen, die hier im Falle eines Faktor den Zeitaufwand verändern oder im Falle einer Sonderleistung eine Zusätzliche Leistung hinzufügt
A11: Spalte Richtfaktor Zeit | B11: Ich sehe bei den Sonderleistungen keinen Faktor, sondern eine echt zu kalkulierende Leistung. Du hast alle drei bereits in der Tabelle "Leistungskatalog " hinterlegt
A12: Mengenfaktor Grundriss | B12: Der Mengenfaktor darf sich nur auf den Umfang und auf die Wandflächen beziehen. Es geht hier nicht klar hervor, ob das so ist oder ob sich der Faktor auch auf Boden und Decke bezieht
A13: Spalte Sonderfaktor Zeit | B13: Wofür steht dieser Faktor? Wann sollte er angepasst werden?
A14: Spalte Zeit inkl Warte min | B14: das hat nur Auswirkung auf Ausführungsdauer und den Zeitrahmen in Form von Tagen., Jedpch nicht auf den Preis. Für den Preis muss (bei Nicht Freigabe von Effizienzen) die Spalte Zeit vor Effizienz min herangezogen werden oder (bei Freigabe Effizienzen) die Spalte Zeit nach Effizienz Min für die Kostenberechnung herangezogen werden
A15: Freigabe aller Räume? | B15: ich kann nicht erkennen, ob die Freigabe der Räume durch den Kunden und eine mögliche Parallelarbeit geprüft wird und ob dann die parallelarbeit an einem Tag in einem anderen Raum genutzt wird. Hier zum Beispiel: wenn am 1. Tag noch Zeit ist, kann im zweiten Raum die Arbeit fortgesetzt werden

Sheet Test-Tabelle
A1: Objekt | B1: Bereich | C1: Mengen-Grundlage | D1: Höhenangabe Raum | E1: Objektangabe Kunde | F1: Formel | G1: Menge X | H1: Menge Decke/Boden | I1: Menge Wände | J1: Faktor Typ | K1: Faktor Menge | L1: Leistung | M1: Sonderleistung | N1: Parallelarbeit Freigabe Kunde | O1: Effizienzstatus | P1: Abdecken | Q1: Abdecken Minuten | R1: Leistung 1 | S1: €-L1 | T1: Minuten-L1 | U1: Wartezeit Minuten | V1: Leistung 3 | W1: Leistung 4 | X1: Leistung 5 | Y1: Leistung 6 | Z1: Leistung 7 | AA1: Leistung 8 | AB1: Leistung 9 | AC1: Leistung 10 | AD1: Spalte 22 | AE1: Spalte 23 | AF1: Column 15
A2: Raum | B2: Wände, Decken | C2: 15 | D2: 2.5 | E2: Raum Normal | H2: =IF(A2="Raum",(C2*J2),"") -> 15 | I2: =IF(A2="Raum",SQRT(C2*J2)*4*D2,"") -> 38.729833 | J2: =IF(E2="Treppenhaus",Faktoren!$G$4,IF(E2="Bad",Faktoren!$G$5,IF(E2="Küche",Faktoren!$G$6,IF(E2="Stuck",Faktoren!$G$7,IF(E2="Sprossenfenster",Faktoren!$G$8,IF(E2="Raum Normal",1,IF(E2="","",""))))))) -> 1 | K2: =IF(E2="Fensterflügel klein",Faktoren!$G$9,IF(E2="Fensterflügel mittel",Faktoren!$G$10,IF(E2="Fensterflügel groß",Faktoren!$G$11,IF(E2="Flur",Faktoren!$G$2,IF(E2="L",Faktoren!$G$3,""))))) | L2: Überholungsanstrich | P2: =IF(A2="Raum",H2*Leistungen!$J$4*(Onboarding!$D$3/60)*(Leistungen!$L$4),"") -> 53.625 | Q2: =IF(A2="Raum",H2*Leistungen!$J$4) -> 45 | R2: =IFERROR(__xludf.DUMMYFUNCTION("INDEX(SPLIT($L$2,"",""),1)"),"Überholungsanstrich") -> Überholungsanstrich | S2: =IFERROR(__xludf.DUMMYFUNCTION("IF(REGEXMATCH(B2,""Decken""),H2,0) + IF(REGEXMATCH(B2,""Wände""),I2,0)*Leistungen!$J$20*(Onboarding!$D$3/60)*Leistungen!$L$20"),216.39513400278565) -> 216.39513 | T2: =IFERROR(__xludf.DUMMYFUNCTION("IF(REGEXMATCH(A2,""Decken""),H2,0) + IF(REGEXMATCH(B2,""Wände""),I2,0)*Leistungen!$J$20"),154.91933384829667) -> 154.91933 | U2: =IFERROR(__xludf.DUMMYFUNCTION("IF(REGEXMATCH(D2,""Decken""),J2,0) + IF(REGEXMATCH(D2,""Wände""),K2,0)*Leistungen!$J$20*(Onboarding!F3/60)*(Leistungen!$L$20)"),"#VALUE!") -> #VALUE! | V2: =IFERROR(__xludf.DUMMYFUNCTION("INDEX(SPLIT($L$2,"",""),3)"),"#REF!") -> #REF! | W2: =IFERROR(__xludf.DUMMYFUNCTION("INDEX(SPLIT($L$2,"",""),4)"),"#REF!") -> #REF! | X2: =IFERROR(__xludf.DUMMYFUNCTION("INDEX(SPLIT($L$2,"",""),5)"),"#REF!") -> #REF! | Y2: =IFERROR(__xludf.DUMMYFUNCTION("INDEX(SPLIT($L$2,"",""),6)"),"#REF!") -> #REF! | Z2: =IFERROR(__xludf.DUMMYFUNCTION("INDEX(SPLIT($L$2,"",""),7)"),"#REF!") -> #REF! | AA2: =IFERROR(__xludf.DUMMYFUNCTION("INDEX(SPLIT($L$2,"",""),8)"),"#REF!") -> #REF! | AB2: =IFERROR(__xludf.DUMMYFUNCTION("INDEX(SPLIT($L$2,"",""),9)"),"#REF!") -> #REF! | AC2: =IFERROR(__xludf.DUMMYFUNCTION("INDEX(SPLIT($L$2,"",""),10)"),"#REF!") -> #REF!
A3: Raum | B3: Wände | C3: 20 | D3: 2.5 | E3: Raum Normal | H3: =IF(A3="Raum",(C3*J3),"") -> 20 | I3: =IF(A3="Raum",SQRT(C3*J3)*4*D3,"") -> 44.72136 | J3: =IF(E3="Treppenhaus",Faktoren!$G$4,IF(E3="Bad",Faktoren!$G$5,IF(E3="Küche",Faktoren!$G$6,IF(E3="Stuck",Faktoren!$G$7,IF(E3="Sprossenfenster",Faktoren!$G$8,IF(E3="Raum Normal",1,IF(E3="","",""))))))) -> 1 | K3: =IF(E3="Fensterflügel klein",Faktoren!$G$9,IF(E3="Fensterflügel mittel",Faktoren!$G$10,IF(E3="Fensterflügel groß",Faktoren!$G$11,IF(E3="Flur",Faktoren!$G$2,IF(E3="L",Faktoren!$G$3,""))))) | L3: Überholungsanstrich | P3: =IF(A3="Raum",H3*Leistungen!$J$4*(Onboarding!$D$3/60)*(Leistungen!$L$4),"") -> 71.5 | Q3: =IF(A3="Raum",H3*Leistungen!$J$4*(Onboarding!$D$3/60)*(Leistungen!$L$4),"") -> 71.5 | R3: =IFERROR(__xludf.DUMMYFUNCTION("INDEX(SPLIT(L3,"",""),1)"),"Überholungsanstrich") -> Überholungsanstrich | S3: =IFERROR(__xludf.DUMMYFUNCTION("IF(REGEXMATCH(B3,""Decken""),H3,0) + IF(REGEXMATCH(B3,""Wände""),I3,0)*Leistungen!$J$20*(Onboarding!$D$3/60)*Leistungen!$L$20"),232.5510696599781) -> 232.55107 | T3: =IFERROR(__xludf.DUMMYFUNCTION("IF(REGEXMATCH(A3,""Decken""),H3,0) + IF(REGEXMATCH(B3,""Wände""),I3,0)*Leistungen!$J$20*(Onboarding!$D$3/60)*Leistungen!$L$20"),232.5510696599781) -> 232.55107 | U3: =IFERROR(__xludf.DUMMYFUNCTION("IF(REGEXMATCH(D3,""Decken""),J3,0) + IF(REGEXMATCH(D3,""Wände""),K3,0)*Leistungen!$J$20*(Onboarding!F4/60)*Leistungen!$L$20"),"#VALUE!") -> #VALUE!
A4: Türen | H4: =IF(A4="Raum",(C4*J4),"") | I4: =IF(A4="Raum",SQRT(C4*J4)*4*D4,"") | J4: =IF(E4="Treppenhaus",Faktoren!$G$4,IF(E4="Bad",Faktoren!$G$5,IF(E4="Küche",Faktoren!$G$6,IF(E4="Stuck",Faktoren!$G$7,IF(E4="Sprossenfenster",Faktoren!$G$8,IF(E4="Raum Normal",1,IF(E4="","",""))))))) | K4: =IF(E4="Fensterflügel klein",Faktoren!$G$9,IF(E4="Fensterflügel mittel",Faktoren!$G$10,IF(E4="Fensterflügel groß",Faktoren!$G$11,IF(E4="Flur",Faktoren!$G$2,IF(E4="L",Faktoren!$G$3,""))))) | P4: =IF(A4="Raum",H4*Leistungen!$J$4*(Onboarding!$D$3/60)*(Leistungen!$L$4),"") | Q4: =IF(A4="Raum",H4*Leistungen!$J$4*(Onboarding!$D$3/60)*(Leistungen!$L$4),"") | R4: =IFERROR(__xludf.DUMMYFUNCTION("INDEX(SPLIT(L4,"",""),1)"),"#VALUE!") -> #VALUE! | S4: =IFERROR(__xludf.DUMMYFUNCTION("IF(REGEXMATCH(B4,""Decken""),H4,0) + IF(REGEXMATCH(B4,""Wände""),I4,0)*Leistungen!$J$20*(Onboarding!$D$3/60)*Leistungen!$L$20"),0.0) -> 0 | T4: =IFERROR(__xludf.DUMMYFUNCTION("IF(REGEXMATCH(A4,""Decken""),H4,0) + IF(REGEXMATCH(B4,""Wände""),I4,0)*Leistungen!$J$20*(Onboarding!$D$3/60)*Leistungen!$L$20"),0.0) -> 0 | U4: =IFERROR(__xludf.DUMMYFUNCTION("IF(REGEXMATCH(D4,""Decken""),J4,0) + IF(REGEXMATCH(D4,""Wände""),K4,0)*Leistungen!$J$20*(Onboarding!F5/60)*Leistungen!$L$20"),"#VALUE!") -> #VALUE!
E5: Flur | H5: =IF(A5="Raum",(C5*J5),"") | I5: =IF(A5="Raum",SQRT(C5*J5)*4*D5,"") | J5: =IF(E5="Treppenhaus",Faktoren!$G$4,IF(E5="Bad",Faktoren!$G$5,IF(E5="Küche",Faktoren!$G$6,IF(E5="Stuck",Faktoren!$G$7,IF(E5="Sprossenfenster",Faktoren!$G$8,IF(E5="Raum Normal",1,IF(E5="","",""))))))) | K5: =IF(E5="Fensterflügel klein",Faktoren!$G$9,IF(E5="Fensterflügel mittel",Faktoren!$G$10,IF(E5="Fensterflügel groß",Faktoren!$G$11,IF(E5="Flur",Faktoren!$G$2,IF(E5="L",Faktoren!$G$3,""))))) -> 45689 | P5: =IF(A5="Raum",H5*Leistungen!$J$4*(Onboarding!$D$3/60)*(Leistungen!$L$4),"") | Q5: =IF(A5="Raum",H5*Leistungen!$J$4*(Onboarding!$D$3/60)*(Leistungen!$L$4),"") | R5: =IFERROR(__xludf.DUMMYFUNCTION("INDEX(SPLIT(L5,"",""),1)"),"#VALUE!") -> #VALUE! | S5: =IFERROR(__xludf.DUMMYFUNCTION("IF(REGEXMATCH(B5,""Decken""),H5,0) + IF(REGEXMATCH(B5,""Wände""),I5,0)*Leistungen!$J$20*(Onboarding!$D$3/60)*Leistungen!$L$20"),0.0) -> 0 | T5: =IFERROR(__xludf.DUMMYFUNCTION("IF(REGEXMATCH(A5,""Decken""),H5,0) + IF(REGEXMATCH(B5,""Wände""),I5,0)*Leistungen!$J$20*(Onboarding!$D$3/60)*Leistungen!$L$20"),0.0) -> 0 | U5: =IFERROR(__xludf.DUMMYFUNCTION("IF(REGEXMATCH(D5,""Decken""),J5,0) + IF(REGEXMATCH(D5,""Wände""),K5,0)*Leistungen!$J$20*(Onboarding!F6/60)*Leistungen!$L$20"),"#VALUE!") -> #VALUE!
H6: =IF(A6="Raum",(C6*J6),"") | I6: =IF(A6="Raum",SQRT(C6*J6)*4*D6,"") | J6: =IF(E6="Treppenhaus",Faktoren!$G$4,IF(E6="Bad",Faktoren!$G$5,IF(E6="Küche",Faktoren!$G$6,IF(E6="Stuck",Faktoren!$G$7,IF(E6="Sprossenfenster",Faktoren!$G$8,IF(E6="Raum Normal",1,IF(E6="","",""))))))) | K6: =IF(E6="Fensterflügel klein",Faktoren!$G$9,IF(E6="Fensterflügel mittel",Faktoren!$G$10,IF(E6="Fensterflügel groß",Faktoren!$G$11,IF(E6="Flur",Faktoren!$G$2,IF(E6="L",Faktoren!$G$3,""))))) | P6: =IF(A6="Raum",H6*Leistungen!$J$4*(Onboarding!$D$3/60)*(Leistungen!$L$4),"") | Q6: =IF(A6="Raum",H6*Leistungen!$J$4*(Onboarding!$D$3/60)*(Leistungen!$L$4),"") | R6: =IFERROR(__xludf.DUMMYFUNCTION("INDEX(SPLIT(L6,"",""),1)"),"#VALUE!") -> #VALUE! | S6: =IFERROR(__xludf.DUMMYFUNCTION("IF(REGEXMATCH(B6,""Decken""),H6,0) + IF(REGEXMATCH(B6,""Wände""),I6,0)*Leistungen!$J$20*(Onboarding!$D$3/60)*Leistungen!$L$20"),0.0) -> 0 | T6: =IFERROR(__xludf.DUMMYFUNCTION("IF(REGEXMATCH(A6,""Decken""),H6,0) + IF(REGEXMATCH(B6,""Wände""),I6,0)*Leistungen!$J$20*(Onboarding!$D$3/60)*Leistungen!$L$20"),0.0) -> 0 | U6: =IFERROR(__xludf.DUMMYFUNCTION("IF(REGEXMATCH(D6,""Decken""),J6,0) + IF(REGEXMATCH(D6,""Wände""),K6,0)*Leistungen!$J$20*(Onboarding!F7/60)*Leistungen!$L$20"),"#VALUE!") -> #VALUE!
H7: =IF(A7="Raum",(C7*J7),"") | I7: =IF(A7="Raum",SQRT(C7*J7)*4*D7,"") | J7: =IF(E7="Treppenhaus",Faktoren!$G$4,IF(E7="Bad",Faktoren!$G$5,IF(E7="Küche",Faktoren!$G$6,IF(E7="Stuck",Faktoren!$G$7,IF(E7="Sprossenfenster",Faktoren!$G$8,IF(E7="Raum Normal",1,IF(E7="","",""))))))) | K7: =IF(E7="Fensterflügel klein",Faktoren!$G$9,IF(E7="Fensterflügel mittel",Faktoren!$G$10,IF(E7="Fensterflügel groß",Faktoren!$G$11,IF(E7="Flur",Faktoren!$G$2,IF(E7="L",Faktoren!$G$3,""))))) | P7: =IF(A7="Raum",H7*Leistungen!$J$4*(Onboarding!$D$3/60)*(Leistungen!$L$4),"") | Q7: =IF(A7="Raum",H7*Leistungen!$J$4*(Onboarding!$D$3/60)*(Leistungen!$L$4),"") | R7: =IFERROR(__xludf.DUMMYFUNCTION("INDEX(SPLIT(L7,"",""),1)"),"#VALUE!") -> #VALUE! | S7: =IFERROR(__xludf.DUMMYFUNCTION("IF(REGEXMATCH(B7,""Decken""),H7,0) + IF(REGEXMATCH(B7,""Wände""),I7,0)*Leistungen!$J$20*(Onboarding!$D$3/60)*Leistungen!$L$20"),0.0) -> 0 | T7: =IFERROR(__xludf.DUMMYFUNCTION("IF(REGEXMATCH(A7,""Decken""),H7,0) + IF(REGEXMATCH(B7,""Wände""),I7,0)*Leistungen!$J$20*(Onboarding!$D$3/60)*Leistungen!$L$20"),0.0) -> 0 | U7: =IFERROR(__xludf.DUMMYFUNCTION("IF(REGEXMATCH(D7,""Decken""),J7,0) + IF(REGEXMATCH(D7,""Wände""),K7,0)*Leistungen!$J$20*(Onboarding!F8/60)*Leistungen!$L$20"),"#VALUE!") -> #VALUE!
H8: =IF(A8="Raum",(C8*J8),"") | I8: =IF(A8="Raum",SQRT(C8*J8)*4*D8,"") | J8: =IF(E8="Treppenhaus",Faktoren!$G$4,IF(E8="Bad",Faktoren!$G$5,IF(E8="Küche",Faktoren!$G$6,IF(E8="Stuck",Faktoren!$G$7,IF(E8="Sprossenfenster",Faktoren!$G$8,IF(E8="Raum Normal",1,IF(E8="","",""))))))) | K8: =IF(E8="Fensterflügel klein",Faktoren!$G$9,IF(E8="Fensterflügel mittel",Faktoren!$G$10,IF(E8="Fensterflügel groß",Faktoren!$G$11,IF(E8="Flur",Faktoren!$G$2,IF(E8="L",Faktoren!$G$3,""))))) | P8: =IF(A8="Raum",H8*Leistungen!$J$4*(Onboarding!$D$3/60)*(Leistungen!$L$4),"") | Q8: =IF(A8="Raum",H8*Leistungen!$J$4*(Onboarding!$D$3/60)*(Leistungen!$L$4),"") | R8: =IFERROR(__xludf.DUMMYFUNCTION("INDEX(SPLIT(L8,"",""),1)"),"#VALUE!") -> #VALUE! | S8: =IFERROR(__xludf.DUMMYFUNCTION("IF(REGEXMATCH(B8,""Decken""),H8,0) + IF(REGEXMATCH(B8,""Wände""),I8,0)*Leistungen!$J$20*(Onboarding!$D$3/60)*Leistungen!$L$20"),0.0) -> 0 | T8: =IFERROR(__xludf.DUMMYFUNCTION("IF(REGEXMATCH(A8,""Decken""),H8,0) + IF(REGEXMATCH(B8,""Wände""),I8,0)*Leistungen!$J$20*(Onboarding!$D$3/60)*Leistungen!$L$20"),0.0) -> 0 | U8: =IFERROR(__xludf.DUMMYFUNCTION("IF(REGEXMATCH(D8,""Decken""),J8,0) + IF(REGEXMATCH(D8,""Wände""),K8,0)*Leistungen!$J$20*(Onboarding!F9/60)*Leistungen!$L$20"),"#VALUE!") -> #VALUE!
H9: =IF(A9="Raum",(C9*J9),"") | I9: =IF(A9="Raum",SQRT(C9*J9)*4*D9,"") | J9: =IF(E9="Treppenhaus",Faktoren!$G$4,IF(E9="Bad",Faktoren!$G$5,IF(E9="Küche",Faktoren!$G$6,IF(E9="Stuck",Faktoren!$G$7,IF(E9="Sprossenfenster",Faktoren!$G$8,IF(E9="Raum Normal",1,IF(E9="","",""))))))) | K9: =IF(E9="Fensterflügel klein",Faktoren!$G$9,IF(E9="Fensterflügel mittel",Faktoren!$G$10,IF(E9="Fensterflügel groß",Faktoren!$G$11,IF(E9="Flur",Faktoren!$G$2,IF(E9="L",Faktoren!$G$3,""))))) | P9: =IF(A9="Raum",H9*Leistungen!$J$4*(Onboarding!$D$3/60)*(Leistungen!$L$4),"") | Q9: =IF(A9="Raum",H9*Leistungen!$J$4*(Onboarding!$D$3/60)*(Leistungen!$L$4),"") | R9: =IFERROR(__xludf.DUMMYFUNCTION("INDEX(SPLIT(L9,"",""),1)"),"#VALUE!") -> #VALUE! | S9: =IFERROR(__xludf.DUMMYFUNCTION("IF(REGEXMATCH(B9,""Decken""),H9,0) + IF(REGEXMATCH(B9,""Wände""),I9,0)*Leistungen!$J$20*(Onboarding!$D$3/60)*Leistungen!$L$20"),0.0) -> 0 | T9: =IFERROR(__xludf.DUMMYFUNCTION("IF(REGEXMATCH(A9,""Decken""),H9,0) + IF(REGEXMATCH(B9,""Wände""),I9,0)*Leistungen!$J$20*(Onboarding!$D$3/60)*Leistungen!$L$20"),0.0) -> 0 | U9: =IFERROR(__xludf.DUMMYFUNCTION("IF(REGEXMATCH(D9,""Decken""),J9,0) + IF(REGEXMATCH(D9,""Wände""),K9,0)*Leistungen!$J$20*(Onboarding!F10/60)*Leistungen!$L$20"),"#VALUE!") -> #VALUE!
H10: =IF(A10="Raum",(C10*J10),"") | I10: =IF(A10="Raum",SQRT(C10*J10)*4*D10,"") | J10: =IF(E10="Treppenhaus",Faktoren!$G$4,IF(E10="Bad",Faktoren!$G$5,IF(E10="Küche",Faktoren!$G$6,IF(E10="Stuck",Faktoren!$G$7,IF(E10="Sprossenfenster",Faktoren!$G$8,IF(E10="Raum Normal",1,IF(E10="","",""))))))) | K10: =IF(E10="Fensterflügel klein",Faktoren!$G$9,IF(E10="Fensterflügel mittel",Faktoren!$G$10,IF(E10="Fensterflügel groß",Faktoren!$G$11,IF(E10="Flur",Faktoren!$G$2,IF(E10="L",Faktoren!$G$3,""))))) | P10: =IF(A10="Raum",H10*Leistungen!$J$4*(Onboarding!$D$3/60)*(Leistungen!$L$4),"") | Q10: =IF(A10="Raum",H10*Leistungen!$J$4*(Onboarding!$D$3/60)*(Leistungen!$L$4),"") | R10: =IFERROR(__xludf.DUMMYFUNCTION("INDEX(SPLIT(L10,"",""),1)"),"#VALUE!") -> #VALUE! | S10: =IFERROR(__xludf.DUMMYFUNCTION("IF(REGEXMATCH(B10,""Decken""),H10,0) + IF(REGEXMATCH(B10,""Wände""),I10,0)*Leistungen!$J$20*(Onboarding!$D$3/60)*Leistungen!$L$20"),0.0) -> 0 | T10: =IFERROR(__xludf.DUMMYFUNCTION("IF(REGEXMATCH(A10,""Decken""),H10,0) + IF(REGEXMATCH(B10,""Wände""),I10,0)*Leistungen!$J$20*(Onboarding!$D$3/60)*Leistungen!$L$20"),0.0) -> 0 | U10: =IFERROR(__xludf.DUMMYFUNCTION("IF(REGEXMATCH(D10,""Decken""),J10,0) + IF(REGEXMATCH(D10,""Wände""),K10,0)*Leistungen!$J$20*(Onboarding!F11/60)*Leistungen!$L$20"),"#VALUE!") -> #VALUE!
H11: =IF(A11="Raum",(C11*J11),"") | I11: =IF(A11="Raum",SQRT(C11*J11)*4*D11,"") | J11: =IF(E11="Treppenhaus",Faktoren!$G$4,IF(E11="Bad",Faktoren!$G$5,IF(E11="Küche",Faktoren!$G$6,IF(E11="Stuck",Faktoren!$G$7,IF(E11="Sprossenfenster",Faktoren!$G$8,IF(E11="Raum Normal",1,IF(E11="","",""))))))) | K11: =IF(E11="Fensterflügel klein",Faktoren!$G$9,IF(E11="Fensterflügel mittel",Faktoren!$G$10,IF(E11="Fensterflügel groß",Faktoren!$G$11,IF(E11="Flur",Faktoren!$G$2,IF(E11="L",Faktoren!$G$3,""))))) | P11: =IF(A11="Raum",H11*Leistungen!$J$4*(Onboarding!$D$3/60)*(Leistungen!$L$4),"") | Q11: =IF(A11="Raum",H11*Leistungen!$J$4*(Onboarding!$D$3/60)*(Leistungen!$L$4),"") | R11: =IFERROR(__xludf.DUMMYFUNCTION("INDEX(SPLIT(L11,"",""),1)"),"#VALUE!") -> #VALUE! | S11: =IFERROR(__xludf.DUMMYFUNCTION("IF(REGEXMATCH(B11,""Decken""),H11,0) + IF(REGEXMATCH(B11,""Wände""),I11,0)*Leistungen!$J$20*(Onboarding!$D$3/60)*Leistungen!$L$20"),0.0) -> 0 | T11: =IFERROR(__xludf.DUMMYFUNCTION("IF(REGEXMATCH(A11,""Decken""),H11,0) + IF(REGEXMATCH(B11,""Wände""),I11,0)*Leistungen!$J$20*(Onboarding!$D$3/60)*Leistungen!$L$20"),0.0) -> 0 | U11: =IFERROR(__xludf.DUMMYFUNCTION("IF(REGEXMATCH(D11,""Decken""),J11,0) + IF(REGEXMATCH(D11,""Wände""),K11,0)*Leistungen!$J$20*(Onboarding!F12/60)*Leistungen!$L$20"),"#VALUE!") -> #VALUE!
H12: =IF(A12="Raum",(C12*J12),"") | I12: =IF(A12="Raum",SQRT(C12*J12)*4*D12,"") | J12: =IF(E12="Treppenhaus",Faktoren!$G$4,IF(E12="Bad",Faktoren!$G$5,IF(E12="Küche",Faktoren!$G$6,IF(E12="Stuck",Faktoren!$G$7,IF(E12="Sprossenfenster",Faktoren!$G$8,IF(E12="Raum Normal",1,IF(E12="","",""))))))) | K12: =IF(E12="Fensterflügel klein",Faktoren!$G$9,IF(E12="Fensterflügel mittel",Faktoren!$G$10,IF(E12="Fensterflügel groß",Faktoren!$G$11,IF(E12="Flur",Faktoren!$G$2,IF(E12="L",Faktoren!$G$3,""))))) | P12: =IF(A12="Raum",H12*Leistungen!$J$4*(Onboarding!$D$3/60)*(Leistungen!$L$4),"") | Q12: =IF(A12="Raum",H12*Leistungen!$J$4*(Onboarding!$D$3/60)*(Leistungen!$L$4),"") | R12: =IFERROR(__xludf.DUMMYFUNCTION("INDEX(SPLIT(L12,"",""),1)"),"#VALUE!") -> #VALUE! | S12: =IFERROR(__xludf.DUMMYFUNCTION("IF(REGEXMATCH(B12,""Decken""),H12,0) + IF(REGEXMATCH(B12,""Wände""),I12,0)*Leistungen!$J$20*(Onboarding!$D$3/60)*Leistungen!$L$20"),0.0) -> 0 | T12: =IFERROR(__xludf.DUMMYFUNCTION("IF(REGEXMATCH(A12,""Decken""),H12,0) + IF(REGEXMATCH(B12,""Wände""),I12,0)*Leistungen!$J$20*(Onboarding!$D$3/60)*Leistungen!$L$20"),0.0) -> 0 | U12: =IFERROR(__xludf.DUMMYFUNCTION("IF(REGEXMATCH(D12,""Decken""),J12,0) + IF(REGEXMATCH(D12,""Wände""),K12,0)*Leistungen!$J$20*(Onboarding!F13/60)*Leistungen!$L$20"),"#VALUE!") -> #VALUE!
H13: =IF(A13="Raum",(C13*J13),"") | I13: =IF(A13="Raum",SQRT(C13*J13)*4*D13,"") | J13: =IF(E13="Treppenhaus",Faktoren!$G$4,IF(E13="Bad",Faktoren!$G$5,IF(E13="Küche",Faktoren!$G$6,IF(E13="Stuck",Faktoren!$G$7,IF(E13="Sprossenfenster",Faktoren!$G$8,IF(E13="Raum Normal",1,IF(E13="","",""))))))) | K13: =IF(E13="Fensterflügel klein",Faktoren!$G$9,IF(E13="Fensterflügel mittel",Faktoren!$G$10,IF(E13="Fensterflügel groß",Faktoren!$G$11,IF(E13="Flur",Faktoren!$G$2,IF(E13="L",Faktoren!$G$3,""))))) | P13: =IF(A13="Raum",H13*Leistungen!$J$4*(Onboarding!$D$3/60)*(Leistungen!$L$4),"") | Q13: =IF(A13="Raum",H13*Leistungen!$J$4*(Onboarding!$D$3/60)*(Leistungen!$L$4),"") | R13: =IFERROR(__xludf.DUMMYFUNCTION("INDEX(SPLIT(L13,"",""),1)"),"#VALUE!") -> #VALUE! | S13: =IFERROR(__xludf.DUMMYFUNCTION("IF(REGEXMATCH(B13,""Decken""),H13,0) + IF(REGEXMATCH(B13,""Wände""),I13,0)*Leistungen!$J$20*(Onboarding!$D$3/60)*Leistungen!$L$20"),0.0) -> 0 | T13: =IFERROR(__xludf.DUMMYFUNCTION("IF(REGEXMATCH(A13,""Decken""),H13,0) + IF(REGEXMATCH(B13,""Wände""),I13,0)*Leistungen!$J$20*(Onboarding!$D$3/60)*Leistungen!$L$20"),0.0) -> 0 | U13: =IFERROR(__xludf.DUMMYFUNCTION("IF(REGEXMATCH(D13,""Decken""),J13,0) + IF(REGEXMATCH(D13,""Wände""),K13,0)*Leistungen!$J$20*(Onboarding!F14/60)*Leistungen!$L$20"),"#VALUE!") -> #VALUE!
H14: =IF(A14="Raum",(C14*J14),"") | I14: =IF(A14="Raum",SQRT(C14*J14)*4*D14,"") | J14: =IF(E14="Treppenhaus",Faktoren!$G$4,IF(E14="Bad",Faktoren!$G$5,IF(E14="Küche",Faktoren!$G$6,IF(E14="Stuck",Faktoren!$G$7,IF(E14="Sprossenfenster",Faktoren!$G$8,IF(E14="Raum Normal",1,IF(E14="","",""))))))) | K14: =IF(E14="Fensterflügel klein",Faktoren!$G$9,IF(E14="Fensterflügel mittel",Faktoren!$G$10,IF(E14="Fensterflügel groß",Faktoren!$G$11,IF(E14="Flur",Faktoren!$G$2,IF(E14="L",Faktoren!$G$3,""))))) | P14: =IF(A14="Raum",H14*Leistungen!$J$4*(Onboarding!$D$3/60)*(Leistungen!$L$4),"") | Q14: =IF(A14="Raum",H14*Leistungen!$J$4*(Onboarding!$D$3/60)*(Leistungen!$L$4),"") | R14: =IFERROR(__xludf.DUMMYFUNCTION("INDEX(SPLIT(L14,"",""),1)"),"#VALUE!") -> #VALUE! | S14: =IFERROR(__xludf.DUMMYFUNCTION("IF(REGEXMATCH(B14,""Decken""),H14,0) + IF(REGEXMATCH(B14,""Wände""),I14,0)*Leistungen!$J$20*(Onboarding!$D$3/60)*Leistungen!$L$20"),0.0) -> 0 | T14: =IFERROR(__xludf.DUMMYFUNCTION("IF(REGEXMATCH(A14,""Decken""),H14,0) + IF(REGEXMATCH(B14,""Wände""),I14,0)*Leistungen!$J$20*(Onboarding!$D$3/60)*Leistungen!$L$20"),0.0) -> 0 | U14: =IFERROR(__xludf.DUMMYFUNCTION("IF(REGEXMATCH(D14,""Decken""),J14,0) + IF(REGEXMATCH(D14,""Wände""),K14,0)*Leistungen!$J$20*(Onboarding!F15/60)*Leistungen!$L$20"),"#VALUE!") -> #VALUE!
H15: =IF(A15="Raum",(C15*J15),"") | I15: =IF(A15="Raum",SQRT(C15*J15)*4*D15,"") | J15: =IF(E15="Treppenhaus",Faktoren!$G$4,IF(E15="Bad",Faktoren!$G$5,IF(E15="Küche",Faktoren!$G$6,IF(E15="Stuck",Faktoren!$G$7,IF(E15="Sprossenfenster",Faktoren!$G$8,IF(E15="Raum Normal",1,IF(E15="","",""))))))) | K15: =IF(E15="Fensterflügel klein",Faktoren!$G$9,IF(E15="Fensterflügel mittel",Faktoren!$G$10,IF(E15="Fensterflügel groß",Faktoren!$G$11,IF(E15="Flur",Faktoren!$G$2,IF(E15="L",Faktoren!$G$3,""))))) | P15: =IF(A15="Raum",H15*Leistungen!$J$4*(Onboarding!$D$3/60)*(Leistungen!$L$4),"") | Q15: =IF(A15="Raum",H15*Leistungen!$J$4*(Onboarding!$D$3/60)*(Leistungen!$L$4),"") | R15: =IFERROR(__xludf.DUMMYFUNCTION("INDEX(SPLIT(L15,"",""),1)"),"#VALUE!") -> #VALUE! | S15: =IFERROR(__xludf.DUMMYFUNCTION("IF(REGEXMATCH(B15,""Decken""),H15,0) + IF(REGEXMATCH(B15,""Wände""),I15,0)*Leistungen!$J$20*(Onboarding!$D$3/60)*Leistungen!$L$20"),0.0) -> 0 | T15: =IFERROR(__xludf.DUMMYFUNCTION("IF(REGEXMATCH(A15,""Decken""),H15,0) + IF(REGEXMATCH(B15,""Wände""),I15,0)*Leistungen!$J$20*(Onboarding!$D$3/60)*Leistungen!$L$20"),0.0) -> 0 | U15: =IFERROR(__xludf.DUMMYFUNCTION("IF(REGEXMATCH(D15,""Decken""),J15,0) + IF(REGEXMATCH(D15,""Wände""),K15,0)*Leistungen!$J$20*(Onboarding!F16/60)*Leistungen!$L$20"),"#VALUE!") -> #VALUE!
H16: =IF(A16="Raum",(C16*J16),"") | I16: =IF(A16="Raum",SQRT(C16*J16)*4*D16,"") | J16: =IF(E16="Treppenhaus",Faktoren!$G$4,IF(E16="Bad",Faktoren!$G$5,IF(E16="Küche",Faktoren!$G$6,IF(E16="Stuck",Faktoren!$G$7,IF(E16="Sprossenfenster",Faktoren!$G$8,IF(E16="Raum Normal",1,IF(E16="","",""))))))) | K16: =IF(E16="Fensterflügel klein",Faktoren!$G$9,IF(E16="Fensterflügel mittel",Faktoren!$G$10,IF(E16="Fensterflügel groß",Faktoren!$G$11,IF(E16="Flur",Faktoren!$G$2,IF(E16="L",Faktoren!$G$3,""))))) | P16: =IF(A16="Raum",H16*Leistungen!$J$4*(Onboarding!$D$3/60)*(Leistungen!$L$4),"") | Q16: =IF(A16="Raum",H16*Leistungen!$J$4*(Onboarding!$D$3/60)*(Leistungen!$L$4),"") | R16: =IFERROR(__xludf.DUMMYFUNCTION("INDEX(SPLIT(L16,"",""),1)"),"#VALUE!") -> #VALUE! | S16: =IFERROR(__xludf.DUMMYFUNCTION("IF(REGEXMATCH(B16,""Decken""),H16,0) + IF(REGEXMATCH(B16,""Wände""),I16,0)*Leistungen!$J$20*(Onboarding!$D$3/60)*Leistungen!$L$20"),0.0) -> 0 | T16: =IFERROR(__xludf.DUMMYFUNCTION("IF(REGEXMATCH(A16,""Decken""),H16,0) + IF(REGEXMATCH(B16,""Wände""),I16,0)*Leistungen!$J$20*(Onboarding!$D$3/60)*Leistungen!$L$20"),0.0) -> 0 | U16: =IFERROR(__xludf.DUMMYFUNCTION("IF(REGEXMATCH(D16,""Decken""),J16,0) + IF(REGEXMATCH(D16,""Wände""),K16,0)*Leistungen!$J$20*(Onboarding!F17/60)*Leistungen!$L$20"),"#VALUE!") -> #VALUE!
H17: =IF(A17="Raum",(C17*J17),"") | I17: =IF(A17="Raum",SQRT(C17*J17)*4*D17,"") | J17: =IF(E17="Treppenhaus",Faktoren!$G$4,IF(E17="Bad",Faktoren!$G$5,IF(E17="Küche",Faktoren!$G$6,IF(E17="Stuck",Faktoren!$G$7,IF(E17="Sprossenfenster",Faktoren!$G$8,IF(E17="Raum Normal",1,IF(E17="","",""))))))) | K17: =IF(E17="Fensterflügel klein",Faktoren!$G$9,IF(E17="Fensterflügel mittel",Faktoren!$G$10,IF(E17="Fensterflügel groß",Faktoren!$G$11,IF(E17="Flur",Faktoren!$G$2,IF(E17="L",Faktoren!$G$3,""))))) | P17: =IF(A17="Raum",H17*Leistungen!$J$4*(Onboarding!$D$3/60)*(Leistungen!$L$4),"") | Q17: =IF(A17="Raum",H17*Leistungen!$J$4*(Onboarding!$D$3/60)*(Leistungen!$L$4),"") | R17: =IFERROR(__xludf.DUMMYFUNCTION("INDEX(SPLIT(L17,"",""),1)"),"#VALUE!") -> #VALUE! | S17: =IFERROR(__xludf.DUMMYFUNCTION("IF(REGEXMATCH(B17,""Decken""),H17,0) + IF(REGEXMATCH(B17,""Wände""),I17,0)*Leistungen!$J$20*(Onboarding!$D$3/60)*Leistungen!$L$20"),0.0) -> 0 | T17: =IFERROR(__xludf.DUMMYFUNCTION("IF(REGEXMATCH(A17,""Decken""),H17,0) + IF(REGEXMATCH(B17,""Wände""),I17,0)*Leistungen!$J$20*(Onboarding!$D$3/60)*Leistungen!$L$20"),0.0) -> 0 | U17: =IFERROR(__xludf.DUMMYFUNCTION("IF(REGEXMATCH(D17,""Decken""),J17,0) + IF(REGEXMATCH(D17,""Wände""),K17,0)*Leistungen!$J$20*(Onboarding!F18/60)*Leistungen!$L$20"),"#VALUE!") -> #VALUE!
H18: =IF(A18="Raum",(C18*J18),"") | I18: =IF(A18="Raum",SQRT(C18*J18)*4*D18,"") | J18: =IF(E18="Treppenhaus",Faktoren!$G$4,IF(E18="Bad",Faktoren!$G$5,IF(E18="Küche",Faktoren!$G$6,IF(E18="Stuck",Faktoren!$G$7,IF(E18="Sprossenfenster",Faktoren!$G$8,IF(E18="Raum Normal",1,IF(E18="","",""))))))) | K18: =IF(E18="Fensterflügel klein",Faktoren!$G$9,IF(E18="Fensterflügel mittel",Faktoren!$G$10,IF(E18="Fensterflügel groß",Faktoren!$G$11,IF(E18="Flur",Faktoren!$G$2,IF(E18="L",Faktoren!$G$3,""))))) | P18: =IF(A18="Raum",H18*Leistungen!$J$4*(Onboarding!$D$3/60)*(Leistungen!$L$4),"") | Q18: =IF(A18="Raum",H18*Leistungen!$J$4*(Onboarding!$D$3/60)*(Leistungen!$L$4),"") | R18: =IFERROR(__xludf.DUMMYFUNCTION("INDEX(SPLIT(L18,"",""),1)"),"#VALUE!") -> #VALUE! | S18: =IFERROR(__xludf.DUMMYFUNCTION("IF(REGEXMATCH(B18,""Decken""),H18,0) + IF(REGEXMATCH(B18,""Wände""),I18,0)*Leistungen!$J$20*(Onboarding!$D$3/60)*Leistungen!$L$20"),0.0) -> 0 | T18: =IFERROR(__xludf.DUMMYFUNCTION("IF(REGEXMATCH(A18,""Decken""),H18,0) + IF(REGEXMATCH(B18,""Wände""),I18,0)*Leistungen!$J$20*(Onboarding!$D$3/60)*Leistungen!$L$20"),0.0) -> 0 | U18: =IFERROR(__xludf.DUMMYFUNCTION("IF(REGEXMATCH(D18,""Decken""),J18,0) + IF(REGEXMATCH(D18,""Wände""),K18,0)*Leistungen!$J$20*(Onboarding!F19/60)*Leistungen!$L$20"),"#VALUE!") -> #VALUE!
H19: =IF(A19="Raum",(C19*J19),"") | I19: =IF(A19="Raum",SQRT(C19*J19)*4*D19,"") | J19: =IF(E19="Treppenhaus",Faktoren!$G$4,IF(E19="Bad",Faktoren!$G$5,IF(E19="Küche",Faktoren!$G$6,IF(E19="Stuck",Faktoren!$G$7,IF(E19="Sprossenfenster",Faktoren!$G$8,IF(E19="Raum Normal",1,IF(E19="","",""))))))) | K19: =IF(E19="Fensterflügel klein",Faktoren!$G$9,IF(E19="Fensterflügel mittel",Faktoren!$G$10,IF(E19="Fensterflügel groß",Faktoren!$G$11,IF(E19="Flur",Faktoren!$G$2,IF(E19="L",Faktoren!$G$3,""))))) | P19: =IF(A19="Raum",H19*Leistungen!$J$4*(Onboarding!$D$3/60)*(Leistungen!$L$4),"") | Q19: =IF(A19="Raum",H19*Leistungen!$J$4*(Onboarding!$D$3/60)*(Leistungen!$L$4),"") | R19: =IFERROR(__xludf.DUMMYFUNCTION("INDEX(SPLIT(L19,"",""),1)"),"#VALUE!") -> #VALUE! | S19: =IFERROR(__xludf.DUMMYFUNCTION("IF(REGEXMATCH(B19,""Decken""),H19,0) + IF(REGEXMATCH(B19,""Wände""),I19,0)*Leistungen!$J$20*(Onboarding!$D$3/60)*Leistungen!$L$20"),0.0) -> 0 | T19: =IFERROR(__xludf.DUMMYFUNCTION("IF(REGEXMATCH(A19,""Decken""),H19,0) + IF(REGEXMATCH(B19,""Wände""),I19,0)*Leistungen!$J$20*(Onboarding!$D$3/60)*Leistungen!$L$20"),0.0) -> 0 | U19: =IFERROR(__xludf.DUMMYFUNCTION("IF(REGEXMATCH(D19,""Decken""),J19,0) + IF(REGEXMATCH(D19,""Wände""),K19,0)*Leistungen!$J$20*(Onboarding!F20/60)*Leistungen!$L$20"),"#VALUE!") -> #VALUE!
H20: =IF(A20="Raum",(C20*J20),"") | I20: =IF(A20="Raum",SQRT(C20*J20)*4*D20,"") | J20: =IF(E20="Treppenhaus",Faktoren!$G$4,IF(E20="Bad",Faktoren!$G$5,IF(E20="Küche",Faktoren!$G$6,IF(E20="Stuck",Faktoren!$G$7,IF(E20="Sprossenfenster",Faktoren!$G$8,IF(E20="Raum Normal",1,IF(E20="","",""))))))) | K20: =IF(E20="Fensterflügel klein",Faktoren!$G$9,IF(E20="Fensterflügel mittel",Faktoren!$G$10,IF(E20="Fensterflügel groß",Faktoren!$G$11,IF(E20="Flur",Faktoren!$G$2,IF(E20="L",Faktoren!$G$3,""))))) | P20: =IF(A20="Raum",H20*Leistungen!$J$4*(Onboarding!$D$3/60)*(Leistungen!$L$4),"") | Q20: =IF(A20="Raum",H20*Leistungen!$J$4*(Onboarding!$D$3/60)*(Leistungen!$L$4),"") | R20: =IFERROR(__xludf.DUMMYFUNCTION("INDEX(SPLIT(L20,"",""),1)"),"#VALUE!") -> #VALUE! | S20: =IFERROR(__xludf.DUMMYFUNCTION("IF(REGEXMATCH(B20,""Decken""),H20,0) + IF(REGEXMATCH(B20,""Wände""),I20,0)*Leistungen!$J$20*(Onboarding!$D$3/60)*Leistungen!$L$20"),0.0) -> 0 | T20: =IFERROR(__xludf.DUMMYFUNCTION("IF(REGEXMATCH(A20,""Decken""),H20,0) + IF(REGEXMATCH(B20,""Wände""),I20,0)*Leistungen!$J$20*(Onboarding!$D$3/60)*Leistungen!$L$20"),0.0) -> 0 | U20: =IFERROR(__xludf.DUMMYFUNCTION("IF(REGEXMATCH(D20,""Decken""),J20,0) + IF(REGEXMATCH(D20,""Wände""),K20,0)*Leistungen!$J$20*(Onboarding!F21/60)*Leistungen!$L$20"),"#VALUE!") -> #VALUE!
H21: =IF(A21="Raum",(C21*J21),"") | I21: =IF(A21="Raum",SQRT(C21*J21)*4*D21,"") | J21: =IF(E21="Treppenhaus",Faktoren!$G$4,IF(E21="Bad",Faktoren!$G$5,IF(E21="Küche",Faktoren!$G$6,IF(E21="Stuck",Faktoren!$G$7,IF(E21="Sprossenfenster",Faktoren!$G$8,IF(E21="Raum Normal",1,IF(E21="","",""))))))) | K21: =IF(E21="Fensterflügel klein",Faktoren!$G$9,IF(E21="Fensterflügel mittel",Faktoren!$G$10,IF(E21="Fensterflügel groß",Faktoren!$G$11,IF(E21="Flur",Faktoren!$G$2,IF(E21="L",Faktoren!$G$3,""))))) | P21: =IF(A21="Raum",H21*Leistungen!$J$4*(Onboarding!$D$3/60)*(Leistungen!$L$4),"") | Q21: =IF(A21="Raum",H21*Leistungen!$J$4*(Onboarding!$D$3/60)*(Leistungen!$L$4),"") | R21: =IFERROR(__xludf.DUMMYFUNCTION("INDEX(SPLIT(L21,"",""),1)"),"#VALUE!") -> #VALUE! | S21: =IFERROR(__xludf.DUMMYFUNCTION("IF(REGEXMATCH(B21,""Decken""),H21,0) + IF(REGEXMATCH(B21,""Wände""),I21,0)*Leistungen!$J$20*(Onboarding!$D$3/60)*Leistungen!$L$20"),0.0) -> 0 | T21: =IFERROR(__xludf.DUMMYFUNCTION("IF(REGEXMATCH(A21,""Decken""),H21,0) + IF(REGEXMATCH(B21,""Wände""),I21,0)*Leistungen!$J$20*(Onboarding!$D$3/60)*Leistungen!$L$20"),0.0) -> 0 | U21: =IFERROR(__xludf.DUMMYFUNCTION("IF(REGEXMATCH(D21,""Decken""),J21,0) + IF(REGEXMATCH(D21,""Wände""),K21,0)*Leistungen!$J$20*(Onboarding!F22/60)*Leistungen!$L$20"),"#VALUE!") -> #VALUE!
H22: =IF(A22="Raum",(C22*J22),"") | I22: =IF(A22="Raum",SQRT(C22*J22)*4*D22,"") | J22: =IF(E22="Treppenhaus",Faktoren!$G$4,IF(E22="Bad",Faktoren!$G$5,IF(E22="Küche",Faktoren!$G$6,IF(E22="Stuck",Faktoren!$G$7,IF(E22="Sprossenfenster",Faktoren!$G$8,IF(E22="Raum Normal",1,IF(E22="","",""))))))) | K22: =IF(E22="Fensterflügel klein",Faktoren!$G$9,IF(E22="Fensterflügel mittel",Faktoren!$G$10,IF(E22="Fensterflügel groß",Faktoren!$G$11,IF(E22="Flur",Faktoren!$G$2,IF(E22="L",Faktoren!$G$3,""))))) | P22: =IF(A22="Raum",H22*Leistungen!$J$4*(Onboarding!$D$3/60)*(Leistungen!$L$4),"") | Q22: =IF(A22="Raum",H22*Leistungen!$J$4*(Onboarding!$D$3/60)*(Leistungen!$L$4),"") | R22: =IFERROR(__xludf.DUMMYFUNCTION("INDEX(SPLIT(L22,"",""),1)"),"#VALUE!") -> #VALUE! | S22: =IFERROR(__xludf.DUMMYFUNCTION("IF(REGEXMATCH(B22,""Decken""),H22,0) + IF(REGEXMATCH(B22,""Wände""),I22,0)*Leistungen!$J$20*(Onboarding!$D$3/60)*Leistungen!$L$20"),0.0) -> 0 | T22: =IFERROR(__xludf.DUMMYFUNCTION("IF(REGEXMATCH(A22,""Decken""),H22,0) + IF(REGEXMATCH(B22,""Wände""),I22,0)*Leistungen!$J$20*(Onboarding!$D$3/60)*Leistungen!$L$20"),0.0) -> 0 | U22: =IFERROR(__xludf.DUMMYFUNCTION("IF(REGEXMATCH(D22,""Decken""),J22,0) + IF(REGEXMATCH(D22,""Wände""),K22,0)*Leistungen!$J$20*(Onboarding!F23/60)*Leistungen!$L$20"),"#VALUE!") -> #VALUE!
H23: =IF(A23="Raum",(C23*J23),"") | I23: =IF(A23="Raum",SQRT(C23*J23)*4*D23,"") | J23: =IF(E23="Treppenhaus",Faktoren!$G$4,IF(E23="Bad",Faktoren!$G$5,IF(E23="Küche",Faktoren!$G$6,IF(E23="Stuck",Faktoren!$G$7,IF(E23="Sprossenfenster",Faktoren!$G$8,IF(E23="Raum Normal",1,IF(E23="","",""))))))) | K23: =IF(E23="Fensterflügel klein",Faktoren!$G$9,IF(E23="Fensterflügel mittel",Faktoren!$G$10,IF(E23="Fensterflügel groß",Faktoren!$G$11,IF(E23="Flur",Faktoren!$G$2,IF(E23="L",Faktoren!$G$3,""))))) | P23: =IF(A23="Raum",H23*Leistungen!$J$4*(Onboarding!$D$3/60)*(Leistungen!$L$4),"") | Q23: =IF(A23="Raum",H23*Leistungen!$J$4*(Onboarding!$D$3/60)*(Leistungen!$L$4),"") | R23: =IFERROR(__xludf.DUMMYFUNCTION("INDEX(SPLIT(L23,"",""),1)"),"#VALUE!") -> #VALUE! | S23: =IFERROR(__xludf.DUMMYFUNCTION("IF(REGEXMATCH(B23,""Decken""),H23,0) + IF(REGEXMATCH(B23,""Wände""),I23,0)*Leistungen!$J$20*(Onboarding!$D$3/60)*Leistungen!$L$20"),0.0) -> 0 | T23: =IFERROR(__xludf.DUMMYFUNCTION("IF(REGEXMATCH(A23,""Decken""),H23,0) + IF(REGEXMATCH(B23,""Wände""),I23,0)*Leistungen!$J$20*(Onboarding!$D$3/60)*Leistungen!$L$20"),0.0) -> 0 | U23: =IFERROR(__xludf.DUMMYFUNCTION("IF(REGEXMATCH(D23,""Decken""),J23,0) + IF(REGEXMATCH(D23,""Wände""),K23,0)*Leistungen!$J$20*(Onboarding!F24/60)*Leistungen!$L$20"),"#VALUE!") -> #VALUE!
H24: =IF(A24="Raum",(C24*J24),"") | I24: =IF(A24="Raum",SQRT(C24*J24)*4*D24,"") | J24: =IF(E24="Treppenhaus",Faktoren!$G$4,IF(E24="Bad",Faktoren!$G$5,IF(E24="Küche",Faktoren!$G$6,IF(E24="Stuck",Faktoren!$G$7,IF(E24="Sprossenfenster",Faktoren!$G$8,IF(E24="Raum Normal",1,IF(E24="","",""))))))) | K24: =IF(E24="Fensterflügel klein",Faktoren!$G$9,IF(E24="Fensterflügel mittel",Faktoren!$G$10,IF(E24="Fensterflügel groß",Faktoren!$G$11,IF(E24="Flur",Faktoren!$G$2,IF(E24="L",Faktoren!$G$3,""))))) | P24: =IF(A24="Raum",H24*Leistungen!$J$4*(Onboarding!$D$3/60)*(Leistungen!$L$4),"") | Q24: =IF(A24="Raum",H24*Leistungen!$J$4*(Onboarding!$D$3/60)*(Leistungen!$L$4),"") | R24: =IFERROR(__xludf.DUMMYFUNCTION("INDEX(SPLIT(L24,"",""),1)"),"#VALUE!") -> #VALUE! | S24: =IFERROR(__xludf.DUMMYFUNCTION("IF(REGEXMATCH(B24,""Decken""),H24,0) + IF(REGEXMATCH(B24,""Wände""),I24,0)*Leistungen!$J$20*(Onboarding!$D$3/60)*Leistungen!$L$20"),0.0) -> 0 | T24: =IFERROR(__xludf.DUMMYFUNCTION("IF(REGEXMATCH(A24,""Decken""),H24,0) + IF(REGEXMATCH(B24,""Wände""),I24,0)*Leistungen!$J$20*(Onboarding!$D$3/60)*Leistungen!$L$20"),0.0) -> 0 | U24: =IFERROR(__xludf.DUMMYFUNCTION("IF(REGEXMATCH(D24,""Decken""),J24,0) + IF(REGEXMATCH(D24,""Wände""),K24,0)*Leistungen!$J$20*(Onboarding!F25/60)*Leistungen!$L$20"),"#VALUE!") -> #VALUE!
H25: =IF(A25="Raum",(C25*J25),"") | I25: =IF(A25="Raum",SQRT(C25*J25)*4*D25,"") | J25: =IF(E25="Treppenhaus",Faktoren!$G$4,IF(E25="Bad",Faktoren!$G$5,IF(E25="Küche",Faktoren!$G$6,IF(E25="Stuck",Faktoren!$G$7,IF(E25="Sprossenfenster",Faktoren!$G$8,IF(E25="Raum Normal",1,IF(E25="","",""))))))) | K25: =IF(E25="Fensterflügel klein",Faktoren!$G$9,IF(E25="Fensterflügel mittel",Faktoren!$G$10,IF(E25="Fensterflügel groß",Faktoren!$G$11,IF(E25="Flur",Faktoren!$G$2,IF(E25="L",Faktoren!$G$3,""))))) | P25: =IF(A25="Raum",H25*Leistungen!$J$4*(Onboarding!$D$3/60)*(Leistungen!$L$4),"") | Q25: =IF(A25="Raum",H25*Leistungen!$J$4*(Onboarding!$D$3/60)*(Leistungen!$L$4),"") | R25: =IFERROR(__xludf.DUMMYFUNCTION("INDEX(SPLIT(L25,"",""),1)"),"#VALUE!") -> #VALUE! | S25: =IFERROR(__xludf.DUMMYFUNCTION("IF(REGEXMATCH(B25,""Decken""),H25,0) + IF(REGEXMATCH(B25,""Wände""),I25,0)*Leistungen!$J$20*(Onboarding!$D$3/60)*Leistungen!$L$20"),0.0) -> 0 | T25: =IFERROR(__xludf.DUMMYFUNCTION("IF(REGEXMATCH(A25,""Decken""),H25,0) + IF(REGEXMATCH(B25,""Wände""),I25,0)*Leistungen!$J$20*(Onboarding!$D$3/60)*Leistungen!$L$20"),0.0) -> 0 | U25: =IFERROR(__xludf.DUMMYFUNCTION("IF(REGEXMATCH(D25,""Decken""),J25,0) + IF(REGEXMATCH(D25,""Wände""),K25,0)*Leistungen!$J$20*(Onboarding!F26/60)*Leistungen!$L$20"),"#VALUE!") -> #VALUE!

Sheet Leistungen
A1: Titel | B1: Übergeordnete Leistung | C1: Leistungstyp | D1: Leistung / Variante | E1: In Leistung enthalten | F1: Einheit | G1: Grenzeffektivität max Einheitsmengen am Tag | H1: Menge Standardfall | I1: Referenzzeit Standardfall | J1: Standartwert je Einheit in Min | K1: Herleitung (min/Einheit & Formel) Standardfall | L1: Material (Standard) | M1: Wartezeit | N1: Mindestzeit /Effizienzsteigerung / Deckel
B2: Global einmalig | C2: Unterleistung Backend | D2: Baustelleneinrichtung | E2: Anfahrt, Ausladen, Wege sichern | F2: h | G2: - | H2: Projektstart einmalig | I2: 45 min | K2: Mindestzeit, sonst Standardmodus (pro Raum/Fläche/Tag) | L2: 1.02 | M2: - | N2: -
B3: Global am Tag | C3: Unterleistung Backend | D3: Mindestzeit am Tag | F3: h | G3: - | H3: Täglich | I3: 1 h 30 min | K3: aus dem Onboarding
B4: Überholungsanstrich, Neuanstrich Decken und Wände, Mustertapete, Malervlies, Raufaser, Tapete entfernen | C4: Unterleistung Backend | D4: Abdecken (Boden) | E4: Abkleben, Folie/Fleece, Ränder fixieren | F4: m² | G4: 110 | H4: 15 m² | I4: 45 min | J4: 3 | K4: 3,0 min/m² (45 min ÷ 15 m²) – Praxiswert | L4: 1.1 | M4: 0 min | N4: Mindestzeit 1h 30 min / Eff. ab 60 m² / Deckel 120 m²
B5: Überholungsanstrich | C5: Unterleistung Backend | D5: Dübellöcher schließen (<10% der Fläche) | E5: Dübellöcher schließen, nachschleifen und vorbessern | F5: m² | G5: 250 | H5: 40 m² | I5: 20 min | J5: 0.5 | K5: 0,5 min/m² ( 20 min / 40 m²) | L5: 1.1 | M5: 30 min | N5: Mindestzeit 1h 30 min / Eff. ab 100 m² / Deckel 250 m²
B6: Raufaser | C6: Unterleistung Backend | D6: Teilspachtelung | E6: punktuell spachteln, schleifen, grundieren | F6: m² | G6: 180 m²/Tag | H6: 40 m² | I6: 8 h 30 min | K6: 12,75 min/m² (510 min ÷ 40 m²) | L6: +5 % | M6: 0,5 Tage | N6: Eff. ab 1 Raum / Deckel 2 Räume
B7: Lackieren, Malervlies, Mustertapete, Neuanstrich Decken und Wände | C7: Unterleistung Backend | D7: Vollflächenspachtelung ≤ 1 mm | E7: vollflächig spachteln, Trocknung, schleifen | F7: m² | G7: 70 m²/Tag (Spachtel) + 175 m²/Tag (Schleifen) | H7: 40 m² | I7: 8,0 h | K7: Spachtel 4,6h + Schliff 1,8h ≈ 6,4h → 8,0h inkl. Rüstzeit | L7: +10 % | M7: 1 Tag | N7: Eff. ab 40 m² / Deckel 70 m²
B8: Überholungsanstrich | C8: Unterleistung Backend | D8: Zusätzlicher Grundanstrich | F8: m² | G8: 180 | H8: 40 m² | I8: 2 h 40 min | J8: 4 | K8: 4,0 min/m² (160 min ÷ 40 m²) | L8: 1.2 | M8: 1–1,5 h | N8: Eff. ab 50 m² / Deckel 160 m²
B9: Überholungsanstrich | C9: Unterleistung Backend | D9: Isoliergrundierung | F9: m² | G9: 180 | H9: 40 m² | I9: 2 h 40 min | J9: 4 | K9: 4,0 min/m² (160 min ÷ 40 m²) | L9: 1.2 | M9: 1–1,5 h | N9: Eff. ab 50 m² / Deckel 160 m²
B10: Bodenbeläge, Raufaser, Malervlies, Mustertapete, Neuanstrich Decken und Wände | C10: Unterleistung Backend | D10: Grundierung (Standard) | E10: staubfrei, Grund auftragen | F10: m² | G10: 180–200 m²/Tag | H10: 40 m² | I10: 2 h 20 min | K10: 3,5 min/m² (140 min ÷ 40 m²) | L10: +5 % | M10: - | N10: Eff. ab 45 m² / Deckel 150 m²
B11: Tapete entfernen | C11: Unterleistung Backend | D11: Boden wasserfest schützen | E11: Folie + dicht verkleben | F11: m² | G11: ~77 m²/Tag | H11: 15 m² | I11: 30 min | K11: 2,0 min/m² (70 % von 3,0 min/m²) | L11: +2 % | M11: -
A12: Beläge entfernen/Abbruch | B12: Tapete entfernen | C12: Unterleistung Backend, Shop Leistung | D12: Tapeten entfernen (Wände + Decken) | E12: Einweichen, abziehen, entsorgen | F12: m² | G12: 60 m²/Tag | H12: 40 m² | I12: 5 h 30 min | K12: 8,25 min/m² (330 min ÷ 40 m²) | L12: 0,50 €/m² | M12: 15 min
B13: Mustertapete | C13: Unterleistung Backend | D13: Farbliche Grundierung | E13: Grundton zur Tapete | F13: m² | G13: 180 m²/Tag | H13: 40 m² | I13: 2 h 40 min | K13: 4,0 min/m² (160 min ÷ 40 m²) | L13: +20 % | M13: 1–1,5 h | N13: Eff. ab 50 m² / Deckel 160 m²
B14: Raufaser, Malervlies, Mustertapete, Global einmalig | C14: Unterleistung Backend | D14: Kleisterauftrag | E14: wand-/bahnenweise einkleistern | F14: m² | G14: ~220 m²/Tag | H14: 40 m² | I14: 2h 30 min | K14: 3,75 min/m² (½ Zeit von Tapezieren) | L14: +2 % | M14: keine | N14: Eff. ab 2 Räume / Deckel 6 Räume
A15: Tapezieren | C15: Shop Titel Leistung | D15: Tapezieren | E15: zuschneiden, kleben, andrücken | F15: m² | G15: 100–120 m²/Tag | H15: 40 m² | I15: 5,0 h | K15: 7,5 min/m² (300 min ÷ 40 m²) | L15: +10 % | M15: - | N15: Eff. ab 60 m² / Deckel 120 m²
A16: Tapezieren | B16: Raufaser | C16: Shop Leistung, Unterleistung Backend | D16: Raufaser
A17: Tapezieren | B17: Malervlies | C17: Shop Leistung, Unterleistung Backend | D17: Malervlies
A18: Tapezieren | B18: Malervlies | C18: Shop Leistung | D18: Mustertapete | E18: Muster ausrichten, kleben | F18: m² | G18: 30 m²/Tag | H18: 20 m² | I18: 5 h 30 min | K18: 16,5 min/m² (330 min ÷ 20 m²) | L18: 10 % + Rollenpreis | M18: - | N18: keine Eff./Deckel
A19: Anstrich | C19: Shop Titel Leistung | D19: Anstrich Decken und Wände
A20: Anstrich | B20: Überholungsanstrich | C20: Shop Leistung | D20: Überholungsanstrich - Streichen (Wände + Decken) | E20: Bauteile (ohne Boden) abkleben, beschneiden, rollen | F20: m² | G20: 150 | H20: 40 m² | I20: 3,0 h | J20: 4 | K20: 4,5 min/m² (180 min ÷ 40 m²) | L20: 1.2 | M20: 60–180 min | N20: Mindestzeit 1h 30 min / Eff. ab 60 m² / Deckel 150 m²
A21: Anstrich | B21: Neuanstrich Decken und Wände | C21: Shop Leistung | D21: Streichen auf frisch gespachtelt | E21: Voranstrich + Schlussanstrich getrennt | F21: m² | G21: – | H21: 40 m² | I21: 3,5 h + 2,5 h | K21: Vor 3,5h + Nach 2,5h mit Trocknung | L21: +15 % | M21: 24 h | N21: Eff./Deckel wie oben
A22: Anstrich | B22: Neuanstrich Decken und Wände | C22: Shop Leistung | D22: Streichen auf Raufasertapete | E22: Raufaser | F22: m² | G22: – | H22: 40 m² | I22: Raufaser 3,5h+2,25h | K22: Nachstruktur beeinflusst Zeit | L22: +15 % | M22: 60–180 min | N22: Eff./Deckel wie oben
A23: Anstrich | B23: Neuanstrich Decken und Wände | C23: Shop Leistung | D23: Streichen auf Malervliestapete | E23: Malervlies | F23: m² | G23: – | H23: 41 m² | I23: Vlies 3,5h+2,5h | K23: Nachstruktur beeinflusst Zeit | L23: +15 % | M23: 60–180 min | N23: Eff./Deckel wie oben
A24: Lackieren | B24: Lackieren | C24: Shop Titel Leistung | D24: Lackieren | E24: schleifen + grundieren, Trocknung, endlackieren | F24: Stk | G24: 4–5 Stk/Tag | H24: 1 Tür | I24: 3,5 h | K24: 1,75h + 1,75h über 2 Tage | L24: +22 % | M24: 6 h | N24: Eff. ab 3 Stk / Deckel 10 Stk
A25: Lackieren | B25: Lackieren | C25: Shop Leistung | D25: Türflügel lackieren (mit Zarge) | E25: schleifen + grundieren, Trocknung, endlackieren | F25: Stk | G25: 4–5 Stk/Tag | H25: 2 Tür | I25: 3,5 h | K25: 1,75h + 1,75h über 2 Tage | L25: +22 % | M25: 7 h | N25: Eff. ab 3 Stk / Deckel 10 Stk
A26: Lackieren | B26: Lackieren | C26: Unterleistung Backend | D26: Türflügel schleifen | F26: Stk | G26: 4–5 Stk/Tag | H26: 3 Tür | I26: 3,5 h | K26: 1,75h + 1,75h über 2 Tage | L26: +22 % | M26: 8 h | N26: Eff. ab 3 Stk / Deckel 10 Stk
A27: Lackieren | B27: Lackieren | C27: Unterleistung Backend | D27: Türflügel grundieren | F27: Stk | G27: 4–5 Stk/Tag | H27: 4 Tür | I27: 3,5 h | K27: 1,75h + 1,75h über 2 Tage | L27: +22 % | M27: 9 h | N27: Eff. ab 3 Stk / Deckel 10 Stk
A28: Lackieren | B28: Lackieren | C28: Unterleistung Backend | D28: Türflügel schlusslackieren | F28: Stk | G28: 4–5 Stk/Tag | H28: 5 Tür | I28: 3,5 h | K28: 1,75h + 1,75h über 2 Tage | L28: +22 % | M28: 10 h | N28: Eff. ab 3 Stk / Deckel 10 Stk
A29: Lackieren | B29: Lackieren | C29: Shop Leistung | D29: Fensterflügel lackieren – je Seite innen (mittel < 1,5 m²) | E29: abkleben, schleifen, grundieren, lackieren | F29: Stk (m²) | G29: 3–4 Stk/Tag | H29: 2 Fensterflügel mittel (<1,5m²) | I29: 5h 45 min | K29: 72 min/m² (180 min ÷ 2,5 m²) | L29: +22 % | M29: 6 h | N29: Eff. ab 3 Stk / Deckel 10 Stk
D30: Fensterflügel innen schleifen | G30: 10 Stk/Tag | H30: 2 Fensterflügel mittel (<1,5m²) | I30: 1 h 30 min
D31: Fensterflügel innen grundieren | G31: 3–4 Stk/Tag | H31: 2 Fensterflügel mittel (<1,5m²) | I31: 2 h
D32: Fensterflügel innen schlusslackieren | G32: 3–4 Stk/Tag | H32: 2 Fensterflügel mittel (<1,5m²) | I32: 2 h 15 min
A33: Lackieren | B33: Lackieren | C33: Shop Leistung | D33: Fensterflügel lackieren – je Seite außen (mittel < 1,5 m²) | E33: wie innen, stärker beansprucht | F33: Stk (m²) | G33: 3–4 Stk/Tag | H33: 2 Fensterflügel mittel (<1,5m²) | I33: 3,5 h | K33: 84 min/m² (210 min ÷ 2,5 m²) | L33: +22 % | M33: 6 h | N33: Eff. ab 3 Stk / Deckel 10 Stk
D34: Fensterflügel außen schleifen | H34: 2 Fensterflügel mittel (<1,5m²) | I34: 2 h 30 min
D35: Fensterflügel außen grundieren | H35: 2 Fensterflügel mittel (<1,5m²) | I35: 2 h 15 min
D36: Fensterflügel außen schlusslackieren | H36: 2 Fensterflügel mittel (<1,5m²) | I36: 2 h 30 min
D38: Aufräumen / Entsorgen | E38: Abfälle sammeln, entsorgen, reinigen | F38: m² | G38: 204 m²/Tag | H38: 44 m² | I38: 1,5 h | K38: 2,25 min/m² (90 min ÷ 40 m²) | L38: - | M38: - | N38: -

Sheet Sonderleistungen
B1: Auswirkung Bereich | C1: Benötigte Zusatzleistung | D1: Auswirkung Leistung | E1: Kathegorie | F1: Objekt | G1: Angabe Sonderleistung | H1: Eingabe | I1: Quelle | J1: UX | K1: Spalte 2 | L1: Spalte 3 | M1: Spalte 4
B2: Decken, Wände, Fenster innen, Türen | C2: Zusätzlicher Grundanstrich | D2: Überholungsanstrich, Lackieren | E2: Leistung | F2: Raum, Fenster, Türen | G2: Verschmutzung/ Verfärbung | H2: Leistungsspezifikation | I2: Onboarding | J2: Wenn der Kunde im Shop die Leistung Überholungsanstrich auswählt, sind mögliche Sonderleistungen hierzu abzufragen. Hier: sind die Oberflächen verschmutzt oder verfärbt
B3: Decken, Wände, Fenster innen, Türen | C3: Isoliergrundierung | D3: Überholungsanstrich, Lackieren | E3: Leistung | F3: Raum, Fenster, Türen | G3: Nikotinverfärbung | H3: Leistungsspezifikation | I3: Onboarding | J3: Wenn der Kunde im Shop die Leistung Überholungsanstrich auswählt, sind mögliche Sonderleistungen hierzu abzufragen. Hier: Wurde in dem Raum geraucht
B4: Wände | C4: Dübellöcher schließen (<10% der Fläche) | D4: Überholungsanstrich | E4: Leistung | F4: Raum | G4: Dübellöcher | H4: Leistungsspezifikation | I4: Onboarding | J4: Wenn der Kunde im Shop die Leistung Überholungsanstrich auswählt, sind mögliche Sonderleistungen hierzu abzufragen. Hier: Sind Dübellöcher in den Wänden zu schließen
C5: Arbeiten werden auf Zeitnachweis tatsächlicher Aufwand ausgeführt | D5: Keine | E5: Leistung | F5: Raum | G5: Umräumarbeiten werden benötigt | H5: Objektverwaltung | I5: Global | J5: hier entsteht nur ein textlicher Platzhalter mit dem Hinweis: Arbeiten werden auf Zeitnachweis tatsächlicher Aufwand ausgeführt und separat abgerechnet

Sheet Faktoren
B1: Auswirkung Bereich | C1: Auswirkung Leistung | D1: Kathegorie | E1: Objekt | F1: Faktorname | G1: Faktor | H1: Eingabe | I1: Quelle | J1: UX | K1: Spalte 2 | L1: Spalte 3 | M1: Spalte 4
B2: Umfang | C2: Keine | D2: Mengen | E2: Raum | F2: Flur | G2: 45689 | H2: Objektverwaltung | I2: Admin SE
B3: Umfang | C3: Keine | D3: Mengen | E3: Raum | F3: L | G3: 45748 | H3: Objektverwaltung | I3: Admin SE, Kunde Shop
B4: Decken, Wände | C4: Tapete entfernen, Raufaser, Malervlies, Mustertapete, Überholungsanstrich, Neuanstrich Decken und Wände | D4: Leistung | E4: Raum | F4: Treppenhaus | G4: 45717 | H4: Objektverwaltung
B5: Decken, Wände | C5: Tapete entfernen, Raufaser, Malervlies, Mustertapete, Überholungsanstrich, Neuanstrich Decken und Wände | D5: Leistung | E5: Raum | F5: Bad | G5: 2.0 | H5: Objektverwaltung
